Workbook
Name __xlfn_CONCAT: NA()
Name __xlfn_IFERROR: NA()
Name __xlfn_SUMIFS: NA()
Name Excel_BuiltIn__FilterDatabase: comp!$C$3:$L$1147

Sheet ins
C3: Bem-vindo à Planilha Sienge Plataforma de Orçamento de Obras 5.0!
D12: Para começar a utilizá-la, vou te explicar como ela funciona:
D15: Base de dados e valores:
D16: Esta planilha usa a base Sinapi SP – SINAPI_Custo_Ref_Composicoes_Analitico_SP_202412_Desonerado. Você pode trocar a base para alguma que faça mais sentido para sua empresa, só lembre de colocar nos mesmos parâmetros da atual na aba ‘Composição Sinapi’.
D19: ACESSE AQUI A BASE SINAPI MAIS RECENTE
D21: As abas
D22: Sintética Preenchimento - Orçamente de forma sintética com resultado somente do total. É a única aba que você irá preencher com os dados de sua obra, no campo 'Quantidade' em VERMELHO. (Há exemplos preenchidos nas informações gerenciais e algumas quantidades de insumos. Apague-os para realizar o preenchimento dos seus dados).
D26: Custo por etapa - Orçamento sintético que detalha os gastos por etapa.
D30: Relatórios' - possui uma tabela com compilação de gastos por etapa.
D33: Dashboard' - possui um conjunto de gráficos que apresentam visualmente os resultados e possibilitam comparações.
D36: Como preencher
D37: * Somente a aba 'Sintetica Preenchimento' precisa ser preenchida, todas as outras abas são preenchidas automaticamente a partir da quantidade preenchida.
D40: * Se for necessário adicionar algum insumo ou composição, uma linha deve ser criada dentro da etapa (na aba que você deseja alterar) e seu preenchimento deve ser feito de acordo com o padrão seguido nas outras linhas. Basta colocar o código do insumo correspondente da aba ‘Composicao Sinapi’ que os demais dados serão completados.
... D50: Aqui você encontra mais materiais úteis e gratuitos para sua empresa!

Sheet sin
C3: Informações Gerenciais | H3: Composição do BDI | K3: Encargos Sociais
C4: Data criação: | E4: 45462 | H4: Administração Central | J4: 0.0389 | K4: 0.22
C5: Data Revisão: | E5: 45470 | H5: Despesas Financeiras | J5: 0.0162
C6: Tipo de Obra: | E6: Residencial MCMV | H6: Garantia/Risco/Seguro | J6: 0.0109
C7: Obra: | E7: Edifício Exemplo | H7: Lucro | J7: 0.0705
C8: Endereço 1: | E8: Rua Exemplo de Souza, número 42 | H8: PIS | J8: 0.03
C9: Endereço 2: | E9: Bairro Mooca, São Paulo/SP | H9: COFINS | J9: 0.05
C10: Responsável: | E10: Carlos Silva | H10: ISS | J10: 0.006
C11: Contato Tel: | E11: 11 99999-9999 | H11: Tributos | J11: =SUM(J8:J10) -> 0.086
C12: Contato Email: | E12: exemplo@exemplo.com.br | H12: Total | J12: =((((1+J4)*(1+J5)*(1+J6)*(1+J7))/(1-J11))-1) -> 0.24997581
C14: Item | D14: Cód. SINAPI | E14: Descrição | I14: Unid. | J14: Qtd. | K14: Valor Unitário | M14: Total
K15: Material | L15: M.O.
C16: 1. | E16: SERVIÇOS INICIAIS
C17: 1.1 | D17: 90778 | E17: =VLOOKUP(D17,comp!D:L,2,FALSE) -> ENGENHEIRO CIVIL DE OBRA PLENO COM ENCARGOS COMPLEMENTARES | I17: =VLOOKUP(D17,comp!D:L,3,FALSE) -> CHP | J17: 5 | K17: =VLOOKUP(D17,comp!D:L,6,FALSE) -> 110.68424 | L17: =VLOOKUP(D17,comp!D:L,7,FALSE) -> 38.435761 | M17: =J17*(K17+L17) -> 745.6
C18: 1.2 | D18: 40819 | E18: =VLOOKUP(D18,comp!D:L,2,FALSE) -> MESTRE DE OBRAS (MENSALISTA) | I18: =VLOOKUP(D18,comp!D:L,3,FALSE) -> MES | J18: 1 | K18: =VLOOKUP(D18,comp!D:L,6,FALSE) -> 0 | L18: =VLOOKUP(D18,comp!D:L,7,FALSE) -> 11155.38 | M18: =J18*(K18+L18) -> 11155.38
C19: 1.3 | D19: 1110 | E19: =VLOOKUP(D19,comp!D:L,2,FALSE) -> CALHA PLATIBANDA DE CHAPA DE ACO GALVANIZADA NUM 26, CORTE 45 CM | I19: =VLOOKUP(D19,comp!D:L,3,FALSE) -> M | J19: 2 | K19: =VLOOKUP(D19,comp!D:L,6,FALSE) -> 30.11 | L19: =VLOOKUP(D19,comp!D:L,7,FALSE) -> 0 | M19: =J19*(K19+L19) -> 60.22
C20: 1.4 | D20: 92265 | E20: =VLOOKUP(D20,comp!D:L,2,FALSE) -> FABRICAÇÃO DE FÔRMA PARA VIGAS, EM CHAPA DE MADEIRA COMPENSADA RESINADA, E = 17 MM. AF_09/2020 | I20: =VLOOKUP(D20,comp!D:L,3,FALSE) -> CHP | J20: 3 | K20: =VLOOKUP(D20,comp!D:L,6,FALSE) -> 104.22179 | L20: =VLOOKUP(D20,comp!D:L,7,FALSE) -> 44.898213 | M20: =J20*(K20+L20) -> 447.36
C21: 1.5 | D21: 88262 | E21: =VLOOKUP(D21,comp!D:L,2,FALSE) -> CARPINTEIRO DE FORMAS COM ENCARGOS COMPLEMENTARES | I21: =VLOOKUP(D21,comp!D:L,3,FALSE) -> CHP | J21: 4 | K21: =VLOOKUP(D21,comp!D:L,6,FALSE) -> 96.448235 | L21: =VLOOKUP(D21,comp!D:L,7,FALSE) -> 52.671765 | M21: =J21*(K21+L21) -> 596.48
C22: 1.6 | D22: 10667 | E22: =VLOOKUP(D22,comp!D:L,2,FALSE) -> CONTAINER ALMOXARIFADO, DE *2,40* X *6,00* M, PADRAO SIMPLES, SEM REVESTIMENTO E SEM DIVISORIAS INTERNOS E SEM SANITARIO, PARA USO EM CANTEIRO DE OBRAS | I22: =VLOOKUP(D22,comp!D:L,3,FALSE) -> UN | J22: 5 | K22: =VLOOKUP(D22,comp!D:L,6,FALSE) -> 0 | L22: =VLOOKUP(D22,comp!D:L,7,FALSE) -> 19404 | M22: =J22*(K22+L22) -> 97020
C23: 1.7 | D23: 37524 | E23: =VLOOKUP(D23,comp!D:L,2,FALSE) -> TELA PLASTICA LARANJA, TIPO TAPUME PARA SINALIZACAO, MALHA RETANGULAR, ROLO 1.20 X 50 M (L X C) | I23: =VLOOKUP(D23,comp!D:L,3,FALSE) -> M | J23: 6 | K23: =VLOOKUP(D23,comp!D:L,6,FALSE) -> 1.89 | L23: =VLOOKUP(D23,comp!D:L,7,FALSE) -> 0 | M23: =J23*(K23+L23) -> 11.34
C24: 1.8 | D24: 39517 | E24: =VLOOKUP(D24,comp!D:L,2,FALSE) -> PAINEL TERMOISOLANTE PARA FECHAMENTOS VERTICAIS (INCLUI PARAFUSOS DE FIXACAO) REVESTIDO EM ACO GALVALUME, LARGURA UTIL DE 1100 MM, REVESTIMENTO COM ESPESSURA DE 0,50 MM, COM PRE-PINTURA NAS DUAS FACES, NUCLEO EM POLIURETANO (PUR) COM ESPESSURA 40/50 MM | I24: =VLOOKUP(D24,comp!D:L,3,FALSE) -> M2 | J24: 7 | K24: =VLOOKUP(D24,comp!D:L,6,FALSE) -> 233.15 | L24: =VLOOKUP(D24,comp!D:L,7,FALSE) -> 0 | M24: =J24*(K24+L24) -> 1632.05
C25: 2. | E25: MOVIMENTAÇÃO DE TERRA
C26: 2.1 | D26: 101616 | E26: =VLOOKUP(D26,comp!D:L,2,FALSE) -> PREPARO DE FUNDO DE VALA COM LARGURA MENOR QUE 1,5 M (ACERTO DO SOLO NATURAL). AF_08/2020 | I26: =VLOOKUP(D26,comp!D:L,3,FALSE) -> CHP | K26: =VLOOKUP(D26,comp!D:L,6,FALSE) -> 104.53945 | L26: =VLOOKUP(D26,comp!D:L,7,FALSE) -> 44.580554 | M26: =J26*(K26+L26) -> 0
C27: 2.2 | D27: 97913 | E27: =VLOOKUP(D27,comp!D:L,2,FALSE) -> TRANSPORTE COM CAMINHÃO BASCULANTE DE 6 M³, EM VIA URBANA EM REVESTIMENTO PRIMÁRIO (UNIDADE: M3XKM). AF_07/2020 | I27: =VLOOKUP(D27,comp!D:L,3,FALSE) -> CHP | K27: =VLOOKUP(D27,comp!D:L,6,FALSE) -> 83.408144 | L27: =VLOOKUP(D27,comp!D:L,7,FALSE) -> 65.711856 | M27: =J27*(K27+L27) -> 0
C28: 2.3 | D28: 5678 | E28: =VLOOKUP(D28,comp!D:L,2,FALSE) -> RETROESCAVADEIRA SOBRE RODAS COM CARREGADEIRA, TRAÇÃO 4X4, POTÊNCIA LÍQ. 88 HP, CAÇAMBA CARREG. CAP. MÍN. 1 M3, CAÇAMBA RETRO CAP. 0,26 M3, PESO OPERACIONAL MÍN. 6.674 KG, PROFUNDIDADE ESCAVAÇÃO MÁX. 4,37 M - CHP DIURNO. AF_06/2014 | I28: =VLOOKUP(D28,comp!D:L,3,FALSE) -> CHP | K28: =VLOOKUP(D28,comp!D:L,6,FALSE) -> 78.356334 | L28: =VLOOKUP(D28,comp!D:L,7,FALSE) -> 70.763666 | M28: =J28*(K28+L28) -> 0
C29: 2.4 | D29: 53786 | E29: =VLOOKUP(D29,comp!D:L,2,FALSE) -> RETROESCAVADEIRA SOBRE RODAS COM CARREGADEIRA, TRAÇÃO 4X4, POTÊNCIA LÍQ. 88 HP, CAÇAMBA CARREG. CAP. MÍN. 1 M3, CAÇAMBA RETRO CAP. 0,26 M3, PESO OPERACIONAL MÍN. 6.674 KG, PROFUNDIDADE ESCAVAÇÃO MÁX. 4,37 M - MATERIAIS NA OPERAÇÃO. AF_06/2014 | I29: =VLOOKUP(D29,comp!D:L,3,FALSE) -> CHP | K29: =VLOOKUP(D29,comp!D:L,6,FALSE) -> 122.39 | L29: =VLOOKUP(D29,comp!D:L,7,FALSE) -> 26.73 | M29: =J29*(K29+L29) -> 0
C30: 2.5 | D30: 40440 | E30: =VLOOKUP(D30,comp!D:L,2,FALSE) -> GABIAO TIPO CAIXA PARA SOLO REFORCADO, MALHA HEXAGONAL 8 X 10 CM (ZN/AL REVESTIDO COM POLIMERO), FIO 2,7 MM, DIMENSOES 2,0 X 1,0 X 0,5 M, COM CAUDA DE 4,0 M | I30: =VLOOKUP(D30,comp!D:L,3,FALSE) -> CHP | K30: =VLOOKUP(D30,comp!D:L,6,FALSE) -> 123.49382 | L30: =VLOOKUP(D30,comp!D:L,7,FALSE) -> 25.626184 | M30: =J30*(K30+L30) -> 0
C31: 3 | E31: FUNDAÇÃO
C32: 3.1 | D32: 12366 | E32: =VLOOKUP(D32,comp!D:L,2,FALSE) -> POSTE DE CONCRETO ARMADO DE SECAO CIRCULAR, EXTENSAO DE 10,00 M, RESISTENCIA DE 150 A 200 DAN, TIPO C-14 | I32: =VLOOKUP(D32,comp!D:L,3,FALSE) -> UN | J32: 9 | K32: =VLOOKUP(D32,comp!D:L,6,FALSE) -> 1046.81 | L32: =VLOOKUP(D32,comp!D:L,7,FALSE) -> 0 | M32: =J32*(K32+L32) -> 9421.29
C33: 3.2 | D33: 40335 | E33: =VLOOKUP(D33,comp!D:L,2,FALSE) -> TUBO DE CONCRETO ARMADO PARA ESGOTO SANITARIO, CLASSE EA-2, COM ENCAIXE PONTA E BOLSA, COM JUNTA ELASTICA, DIAMETRO NOMINAL DE 300 MM | I33: =VLOOKUP(D33,comp!D:L,3,FALSE) -> CHP | K33: =VLOOKUP(D33,comp!D:L,6,FALSE) -> 145.81224 | L33: =VLOOKUP(D33,comp!D:L,7,FALSE) -> 3.3077622 | M33: =J33*(K33+L33) -> 0
C34: 3.3 | D34: 7740 | E34: =VLOOKUP(D34,comp!D:L,2,FALSE) -> TUBO DE CONCRETO ARMADO PARA ESGOTO SANITARIO, CLASSE EA-2, COM ENCAIXE PONTA E BOLSA, COM JUNTA ELASTICA, DIAMETRO NOMINAL DE 400 MM | I34: =VLOOKUP(D34,comp!D:L,3,FALSE) -> CHP | K34: =VLOOKUP(D34,comp!D:L,6,FALSE) -> 144.64151 | L34: =VLOOKUP(D34,comp!D:L,7,FALSE) -> 4.4784923 | M34: =J34*(K34+L34) -> 0
C35: 3.4 | D35: 34583 | E35: =VLOOKUP(D35,comp!D:L,2,FALSE) -> BLOCO DE GESSO COMPACTO / MACICO, BRANCO, E = 10 CM, DIMENSOES *67 X 50* CM | I35: =VLOOKUP(D35,comp!D:L,3,FALSE) -> M2 | K35: =VLOOKUP(D35,comp!D:L,6,FALSE) -> 56.04 | L35: =VLOOKUP(D35,comp!D:L,7,FALSE) -> 0 | M35: =J35*(K35+L35) -> 0
C36: 3.5 | D36: 88307 | E36: =VLOOKUP(D36,comp!D:L,2,FALSE) -> OPERADOR PARA BATE ESTACAS COM ENCARGOS COMPLEMENTARES | I36: =VLOOKUP(D36,comp!D:L,3,FALSE) -> CHP | K36: =VLOOKUP(D36,comp!D:L,6,FALSE) -> 119.46297 | L36: =VLOOKUP(D36,comp!D:L,7,FALSE) -> 29.657034 | M36: =J36*(K36+L36) -> 0
C37: 3.6 | D37: 89212 | E37: =VLOOKUP(D37,comp!D:L,2,FALSE) -> BATE-ESTACAS POR GRAVIDADE, POTÊNCIA DE 160 HP, PESO DO MARTELO ATÉ 3 TONELADAS - DEPRECIAÇÃO. AF_11/2014 | I37: =VLOOKUP(D37,comp!D:L,3,FALSE) -> CHP | K37: =VLOOKUP(D37,comp!D:L,6,FALSE) -> 119.46297 | L37: =VLOOKUP(D37,comp!D:L,7,FALSE) -> 29.657034 | M37: =J37*(K37+L37) -> 0
C38: 3.7 | D38: 38542 | E38: =VLOOKUP(D38,comp!D:L,2,FALSE) -> PERFURATRIZ COM TORRE METALICA PARA EXECUCAO DE ESTACA HELICE CONTINUA, PROFUNDIDADE MAXIMA DE 32 M, DIAMETRO MAXIMO DE 1000 MM, POTENCIA INSTALADA DE 350 HP, MESA ROTATIVA COM TORQUE MAXIMO DE 263 KNM | I38: =VLOOKUP(D38,comp!D:L,3,FALSE) -> CHP | K38: =VLOOKUP(D38,comp!D:L,6,FALSE) -> 149.12 | L38: =VLOOKUP(D38,comp!D:L,7,FALSE) -> 0 | M38: =J38*(K38+L38) -> 0
C39: 3.8 | D39: 44003 | E39: =VLOOKUP(D39,comp!D:L,2,FALSE) -> PERFURATRIZ PARA EXECUCAO DE ESTACAS SECANTES, TIPO HELICE CONTINUA COM CABECOTE DUPLO E TUBO METALICO 300 KW | I39: =VLOOKUP(D39,comp!D:L,3,FALSE) -> CHP | K39: =VLOOKUP(D39,comp!D:L,6,FALSE) -> 149.12 | L39: =VLOOKUP(D39,comp!D:L,7,FALSE) -> 0 | M39: =J39*(K39+L39) -> 0
C40: 3.9 | D40: 38538 | E40: =VLOOKUP(D40,comp!D:L,2,FALSE) -> ESTACA PRE-MOLDADA MACICA DE CONCRETO VIBRADO ARMADO, PARA CARGA DE 25 T, SECAO QUADRADA DE *16 X 16*, COM ANEL METALICO INCORPORADO A PECA (SOMENTE FORNECIMENTO) | I40: =VLOOKUP(D40,comp!D:L,3,FALSE) -> CHP | K40: =VLOOKUP(D40,comp!D:L,6,FALSE) -> 132.2291 | L40: =VLOOKUP(D40,comp!D:L,7,FALSE) -> 16.890904 | M40: =J40*(K40+L40) -> 0
C41: 3.10 | D41: 38540 | E41: =VLOOKUP(D41,comp!D:L,2,FALSE) -> ESTACA PRE-MOLDADA VAZADA DE CONCRETO CENTRIFUGADO, PARA CARGA DE 100 T, SECAO CIRCULAR, COM ANEL METALICO INCORPORADO A PECA (SOMENTE FORNECIMENTO) | I41: =VLOOKUP(D41,comp!D:L,3,FALSE) -> CHP | K41: =VLOOKUP(D41,comp!D:L,6,FALSE) -> 140.88092 | L41: =VLOOKUP(D41,comp!D:L,7,FALSE) -> 8.2390797 | M41: =J41*(K41+L41) -> 0
C42: 4 | E42: ESTRUTURA EM CONCRETO ARMADO
C43: 4.1 | D43: 96620 | E43: =VLOOKUP(D43,comp!D:L,2,FALSE) -> LASTRO DE CONCRETO MAGRO, APLICADO EM PISOS, LAJES SOBRE SOLO OU RADIERS. AF_01/2024 | I43: =VLOOKUP(D43,comp!D:L,3,FALSE) -> CHP | J43: 8 | K43: =VLOOKUP(D43,comp!D:L,6,FALSE) -> 112.74393 | L43: =VLOOKUP(D43,comp!D:L,7,FALSE) -> 36.376073 | M43: =J43*(K43+L43) -> 1192.96
...

Sheet cpe
C3: Data criação: | E3: =sin!E4 -> 45462 | G3: Data Revisão: | H3: =sin!E5 -> 45470
C4: Obra: | E4: =sin!E4 -> 45462 | G4: BDI: | H4: =sin!J12 -> 0.24997581
C5: Tipo de Obra: | E5: =sin!E6 -> Residencial MCMV | G5: Encargos Sociais: | H5: =sin!K4 -> 0.22
C6: Endereço: | E6: =sin!E8 -> Rua Exemplo de Souza, número 42 | H6: =sin!E9 -> Bairro Mooca, São Paulo/SP
C8: Item | D8: Cód. SINAPI | E8: Descrição | J8: Unid. | K8: Qtd. | L8: Valor Unitário | N8: Total
L9: Material | M9: M.O.
C10: 1. | E10: SERVIÇOS INICIAIS
C11: 1.1 | D11: 90778 | E11: =VLOOKUP(D11,comp!$D$5:$K$7114,2,FALSE) -> ENGENHEIRO CIVIL DE OBRA PLENO COM ENCARGOS COMPLEMENTARES | J11: =VLOOKUP(D11,comp!$D$5:$K$7114,3,FALSE) -> CHP | K11: =_xlfn.XLOOKUP(D11, sin!D:D, sin!J:J, "Não Encontrado", 0,1) -> 5 | L11: =VLOOKUP(D11,comp!$D$5:$K$7114,6,FALSE) -> 110.68424 | M11: =VLOOKUP(D11,comp!$D$5:$K$7114,7,FALSE) -> 38.435761 | N11: =K11*(L11+M11) -> 745.6
C12: 1.2 | D12: 40819 | E12: =VLOOKUP(D12,comp!$D$5:$K$7114,2,FALSE) -> MESTRE DE OBRAS (MENSALISTA) | J12: =VLOOKUP(D12,comp!$D$5:$K$7114,3,FALSE) -> MES | K12: =_xlfn.XLOOKUP(D12, sin!D:D, sin!J:J, "Não Encontrado", 0,1) -> 1 | L12: =VLOOKUP(D12,comp!$D$5:$K$7114,6,FALSE) -> 0 | M12: =VLOOKUP(D12,comp!$D$5:$K$7114,7,FALSE) -> 11155.38 | N12: =K12*(L12+M12) -> 11155.38
C13: 1.3 | D13: 1110 | E13: =VLOOKUP(D13,comp!$D$5:$K$7114,2,FALSE) -> CALHA PLATIBANDA DE CHAPA DE ACO GALVANIZADA NUM 26, CORTE 45 CM | J13: =VLOOKUP(D13,comp!$D$5:$K$7114,3,FALSE) -> M | K13: =_xlfn.XLOOKUP(D13, sin!D:D, sin!J:J, "Não Encontrado", 0,1) -> 2 | L13: =VLOOKUP(D13,comp!$D$5:$K$7114,6,FALSE) -> 30.11 | M13: =VLOOKUP(D13,comp!$D$5:$K$7114,7,FALSE) -> 0 | N13: =K13*(L13+M13) -> 60.22
C14: 1.4 | D14: 92265 | E14: =VLOOKUP(D14,comp!$D$5:$K$7114,2,FALSE) -> FABRICAÇÃO DE FÔRMA PARA VIGAS, EM CHAPA DE MADEIRA COMPENSADA RESINADA, E = 17 MM. AF_09/2020 | J14: =VLOOKUP(D14,comp!$D$5:$K$7114,3,FALSE) -> CHP | K14: =_xlfn.XLOOKUP(D14, sin!D:D, sin!J:J, "Não Encontrado", 0,1) -> 3 | L14: =VLOOKUP(D14,comp!$D$5:$K$7114,6,FALSE) -> 104.22179 | M14: =VLOOKUP(D14,comp!$D$5:$K$7114,7,FALSE) -> 44.898213 | N14: =K14*(L14+M14) -> 447.36
C15: 1.5 | D15: 88262 | E15: =VLOOKUP(D15,comp!$D$5:$K$7114,2,FALSE) -> CARPINTEIRO DE FORMAS COM ENCARGOS COMPLEMENTARES | J15: =VLOOKUP(D15,comp!$D$5:$K$7114,3,FALSE) -> CHP | K15: =_xlfn.XLOOKUP(D15, sin!D:D, sin!J:J, "Não Encontrado", 0,1) -> 4 | L15: =VLOOKUP(D15,comp!$D$5:$K$7114,6,FALSE) -> 96.448235 | M15: =VLOOKUP(D15,comp!$D$5:$K$7114,7,FALSE) -> 52.671765 | N15: =K15*(L15+M15) -> 596.48
C16: 1.6 | D16: 10667 | E16: =VLOOKUP(D16,comp!$D$5:$K$7114,2,FALSE) -> CONTAINER ALMOXARIFADO, DE *2,40* X *6,00* M, PADRAO SIMPLES, SEM REVESTIMENTO E SEM DIVISORIAS INTERNOS E SEM SANITARIO, PARA USO EM CANTEIRO DE OBRAS | J16: =VLOOKUP(D16,comp!$D$5:$K$7114,3,FALSE) -> UN | K16: =_xlfn.XLOOKUP(D16, sin!D:D, sin!J:J, "Não Encontrado", 0,1) -> 5 | L16: =VLOOKUP(D16,comp!$D$5:$K$7114,6,FALSE) -> 0 | M16: =VLOOKUP(D16,comp!$D$5:$K$7114,7,FALSE) -> 19404 | N16: =K16*(L16+M16) -> 97020
C17: 1.7 | D17: 37524 | E17: =VLOOKUP(D17,comp!$D$5:$K$7114,2,FALSE) -> TELA PLASTICA LARANJA, TIPO TAPUME PARA SINALIZACAO, MALHA RETANGULAR, ROLO 1.20 X 50 M (L X C) | J17: =VLOOKUP(D17,comp!$D$5:$K$7114,3,FALSE) -> M | K17: =_xlfn.XLOOKUP(D17, sin!D:D, sin!J:J, "Não Encontrado", 0,1) -> 6 | L17: =VLOOKUP(D17,comp!$D$5:$K$7114,6,FALSE) -> 1.89 | M17: =VLOOKUP(D17,comp!$D$5:$K$7114,7,FALSE) -> 0 | N17: =K17*(L17+M17) -> 11.34
C18: 1.8 | D18: 39517 | E18: =VLOOKUP(D18,comp!$D$5:$K$7114,2,FALSE) -> PAINEL TERMOISOLANTE PARA FECHAMENTOS VERTICAIS (INCLUI PARAFUSOS DE FIXACAO) REVESTIDO EM ACO GALVALUME, LARGURA UTIL DE 1100 MM, REVESTIMENTO COM ESPESSURA DE 0,50 MM, COM PRE-PINTURA NAS DUAS FACES, NUCLEO EM POLIURETANO (PUR) COM ESPESSURA 40/50 MM | J18: =VLOOKUP(D18,comp!$D$5:$K$7114,3,FALSE) -> M2 | K18: =_xlfn.XLOOKUP(D18, sin!D:D, sin!J:J, "Não Encontrado", 0,1) -> 7 | L18: =VLOOKUP(D18,comp!$D$5:$K$7114,6,FALSE) -> 233.15 | M18: =VLOOKUP(D18,comp!$D$5:$K$7114,7,FALSE) -> 0 | N18: =K18*(L18+M18) -> 1632.05
J19: M.O = | K19: {=SUMPRODUCT(K11:K18*M11:M18)} -> 108712.94 | L19: Total = | N19: =SUM(K19:K20) -> 111668.43
J20: Outros = | K20: {=SUMPRODUCT(K11:K18*L11:L18)} -> 2955.4895 | L20: LS = | N20: =K19*$H$5 -> 23916.847
L21: BDI = | N21: =(N20+N19)*$H$4 -> 33893.04
L22: Valor Total = | N22: =SUM(N19:N21) -> 169478.32
C23: 2. | E23: MOVIMENTAÇÃO DE TERRA
C24: 2.1 | D24: 101616 | E24: =VLOOKUP(D24,comp!$D$5:$K$7114,2,FALSE) -> PREPARO DE FUNDO DE VALA COM LARGURA MENOR QUE 1,5 M (ACERTO DO SOLO NATURAL). AF_08/2020 | J24: =VLOOKUP(D24,comp!$D$5:$K$7114,3,FALSE) -> CHP | K24: =_xlfn.XLOOKUP(D24, sin!D:D, sin!J:J, "Não Encontrado", 0,1) -> 0 | L24: =VLOOKUP(D24,comp!$D$5:$K$7114,6,FALSE) -> 104.53945 | M24: =VLOOKUP(D24,comp!$D$5:$K$7114,7,FALSE) -> 44.580554 | N24: =K24*(L24+M24) -> 0
C25: 2.2 | D25: 97913 | E25: =VLOOKUP(D25,comp!$D$5:$K$7114,2,FALSE) -> TRANSPORTE COM CAMINHÃO BASCULANTE DE 6 M³, EM VIA URBANA EM REVESTIMENTO PRIMÁRIO (UNIDADE: M3XKM). AF_07/2020 | J25: =VLOOKUP(D25,comp!$D$5:$K$7114,3,FALSE) -> CHP | K25: =_xlfn.XLOOKUP(D25, sin!D:D, sin!J:J, "Não Encontrado", 0,1) -> 0 | L25: =VLOOKUP(D25,comp!$D$5:$K$7114,6,FALSE) -> 83.408144 | M25: =VLOOKUP(D25,comp!$D$5:$K$7114,7,FALSE) -> 65.711856 | N25: =K25*(L25+M25) -> 0
C26: 2.3 | D26: 5678 | E26: =VLOOKUP(D26,comp!$D$5:$K$7114,2,FALSE) -> RETROESCAVADEIRA SOBRE RODAS COM CARREGADEIRA, TRAÇÃO 4X4, POTÊNCIA LÍQ. 88 HP, CAÇAMBA CARREG. CAP. MÍN. 1 M3, CAÇAMBA RETRO CAP. 0,26 M3, PESO OPERACIONAL MÍN. 6.674 KG, PROFUNDIDADE ESCAVAÇÃO MÁX. 4,37 M - CHP DIURNO. AF_06/2014 | J26: =VLOOKUP(D26,comp!$D$5:$K$7114,3,FALSE) -> CHP | K26: =_xlfn.XLOOKUP(D26, sin!D:D, sin!J:J, "Não Encontrado", 0,1) -> 0 | L26: =VLOOKUP(D26,comp!$D$5:$K$7114,6,FALSE) -> 78.356334 | M26: =VLOOKUP(D26,comp!$D$5:$K$7114,7,FALSE) -> 70.763666 | N26: =K26*(L26+M26) -> 0
C27: 2.4 | D27: 53786 | E27: =VLOOKUP(D27,comp!$D$5:$K$7114,2,FALSE) -> RETROESCAVADEIRA SOBRE RODAS COM CARREGADEIRA, TRAÇÃO 4X4, POTÊNCIA LÍQ. 88 HP, CAÇAMBA CARREG. CAP. MÍN. 1 M3, CAÇAMBA RETRO CAP. 0,26 M3, PESO OPERACIONAL MÍN. 6.674 KG, PROFUNDIDADE ESCAVAÇÃO MÁX. 4,37 M - MATERIAIS NA OPERAÇÃO. AF_06/2014 | J27: =VLOOKUP(D27,comp!$D$5:$K$7114,3,FALSE) -> CHP | K27: =_xlfn.XLOOKUP(D27, sin!D:D, sin!J:J, "Não Encontrado", 0,1) -> 0 | L27: =VLOOKUP(D27,comp!$D$5:$K$7114,6,FALSE) -> 122.39 | M27: =VLOOKUP(D27,comp!$D$5:$K$7114,7,FALSE) -> 26.73 | N27: =K27*(L27+M27) -> 0
C28: 2.5 | D28: 40440 | E28: =VLOOKUP(D28,comp!$D$5:$K$7114,2,FALSE) -> GABIAO TIPO CAIXA PARA SOLO REFORCADO, MALHA HEXAGONAL 8 X 10 CM (ZN/AL REVESTIDO COM POLIMERO), FIO 2,7 MM, DIMENSOES 2,0 X 1,0 X 0,5 M, COM CAUDA DE 4,0 M | J28: =VLOOKUP(D28,comp!$D$5:$K$7114,3,FALSE) -> CHP | K28: =_xlfn.XLOOKUP(D28, sin!D:D, sin!J:J, "Não Encontrado", 0,1) -> 0 | L28: =VLOOKUP(D28,comp!$D$5:$K$7114,6,FALSE) -> 123.49382 | M28: =VLOOKUP(D28,comp!$D$5:$K$7114,7,FALSE) -> 25.626184 | N28: =K28*(L28+M28) -> 0
J29: M.O = | K29: =SUMPRODUCT(K24:K28*M24:M28) -> 0 | L29: Total = | N29: =SUM(K29:K30) -> 0
J30: Outros = | K30: =SUMPRODUCT(K24:K28*L24:L28) -> 0 | L30: LS = | N30: =K29*$H$5 -> 0
L31: BDI = | N31: =(N30+N29)*$H$4 -> 0
L32: Valor Total = | N32: =SUM(N29:N31) -> 0
C33: 3 | E33: FUNDAÇÃO
C34: 3.1 | D34: 12366 | E34: =VLOOKUP(D34,comp!$D$5:$K$7114,2,FALSE) -> POSTE DE CONCRETO ARMADO DE SECAO CIRCULAR, EXTENSAO DE 10,00 M, RESISTENCIA DE 150 A 200 DAN, TIPO C-14 | J34: =VLOOKUP(D34,comp!$D$5:$K$7114,3,FALSE) -> UN | K34: =_xlfn.XLOOKUP(D34, sin!D:D, sin!J:J, "Não Encontrado", 0,1) -> 9 | L34: =VLOOKUP(D34,comp!$D$5:$K$7114,6,FALSE) -> 1046.81 | M34: =VLOOKUP(D34,comp!$D$5:$K$7114,7,FALSE) -> 0 | N34: =K34*(L34+M34) -> 9421.29
C35: 3.2 | D35: 40335 | E35: =VLOOKUP(D35,comp!$D$5:$K$7114,2,FALSE) -> TUBO DE CONCRETO ARMADO PARA ESGOTO SANITARIO, CLASSE EA-2, COM ENCAIXE PONTA E BOLSA, COM JUNTA ELASTICA, DIAMETRO NOMINAL DE 300 MM | J35: =VLOOKUP(D35,comp!$D$5:$K$7114,3,FALSE) -> CHP | K35: =_xlfn.XLOOKUP(D35, sin!D:D, sin!J:J, "Não Encontrado", 0,1) -> 0 | L35: =VLOOKUP(D35,comp!$D$5:$K$7114,6,FALSE) -> 145.81224 | M35: =VLOOKUP(D35,comp!$D$5:$K$7114,7,FALSE) -> 3.3077622 | N35: =K35*(L35+M35) -> 0
C36: 3.3 | D36: 7740 | E36: =VLOOKUP(D36,comp!$D$5:$K$7114,2,FALSE) -> TUBO DE CONCRETO ARMADO PARA ESGOTO SANITARIO, CLASSE EA-2, COM ENCAIXE PONTA E BOLSA, COM JUNTA ELASTICA, DIAMETRO NOMINAL DE 400 MM | J36: =VLOOKUP(D36,comp!$D$5:$K$7114,3,FALSE) -> CHP | K36: =_xlfn.XLOOKUP(D36, sin!D:D, sin!J:J, "Não Encontrado", 0,1) -> 0 | L36: =VLOOKUP(D36,comp!$D$5:$K$7114,6,FALSE) -> 144.64151 | M36: =VLOOKUP(D36,comp!$D$5:$K$7114,7,FALSE) -> 4.4784923 | N36: =K36*(L36+M36) -> 0
C37: 3.4 | D37: 34583 | E37: =VLOOKUP(D37,comp!$D$5:$K$7114,2,FALSE) -> BLOCO DE GESSO COMPACTO / MACICO, BRANCO, E = 10 CM, DIMENSOES *67 X 50* CM | J37: =VLOOKUP(D37,comp!$D$5:$K$7114,3,FALSE) -> M2 | K37: =_xlfn.XLOOKUP(D37, sin!D:D, sin!J:J, "Não Encontrado", 0,1) -> 0 | L37: =VLOOKUP(D37,comp!$D$5:$K$7114,6,FALSE) -> 56.04 | M37: =VLOOKUP(D37,comp!$D$5:$K$7114,7,FALSE) -> 0 | N37: =K37*(L37+M37) -> 0
C38: 3.5 | D38: 88307 | E38: =VLOOKUP(D38,comp!$D$5:$K$7114,2,FALSE) -> OPERADOR PARA BATE ESTACAS COM ENCARGOS COMPLEMENTARES | J38: =VLOOKUP(D38,comp!$D$5:$K$7114,3,FALSE) -> CHP | K38: =_xlfn.XLOOKUP(D38, sin!D:D, sin!J:J, "Não Encontrado", 0,1) -> 0 | L38: =VLOOKUP(D38,comp!$D$5:$K$7114,6,FALSE) -> 119.46297 | M38: =VLOOKUP(D38,comp!$D$5:$K$7114,7,FALSE) -> 29.657034 | N38: =K38*(L38+M38) -> 0
C39: 3.6 | D39: 89212 | E39: =VLOOKUP(D39,comp!$D$5:$K$7114,2,FALSE) -> BATE-ESTACAS POR GRAVIDADE, POTÊNCIA DE 160 HP, PESO DO MARTELO ATÉ 3 TONELADAS - DEPRECIAÇÃO. AF_11/2014 | J39: =VLOOKUP(D39,comp!$D$5:$K$7114,3,FALSE) -> CHP | K39: =_xlfn.XLOOKUP(D39, sin!D:D, sin!J:J, "Não Encontrado", 0,1) -> 0 | L39: =VLOOKUP(D39,comp!$D$5:$K$7114,6,FALSE) -> 119.46297 | M39: =VLOOKUP(D39,comp!$D$5:$K$7114,7,FALSE) -> 29.657034 | N39: =K39*(L39+M39) -> 0
C40: 3.7 | D40: 38542 | E40: =VLOOKUP(D40,comp!$D$5:$K$7114,2,FALSE) -> PERFURATRIZ COM TORRE METALICA PARA EXECUCAO DE ESTACA HELICE CONTINUA, PROFUNDIDADE MAXIMA DE 32 M, DIAMETRO MAXIMO DE 1000 MM, POTENCIA INSTALADA DE 350 HP, MESA ROTATIVA COM TORQUE MAXIMO DE 263 KNM | J40: =VLOOKUP(D40,comp!$D$5:$K$7114,3,FALSE) -> CHP | K40: =_xlfn.XLOOKUP(D40, sin!D:D, sin!J:J, "Não Encontrado", 0,1) -> 0 | L40: =VLOOKUP(D40,comp!$D$5:$K$7114,6,FALSE) -> 149.12 | M40: =VLOOKUP(D40,comp!$D$5:$K$7114,7,FALSE) -> 0 | N40: =K40*(L40+M40) -> 0
C41: 3.8 | D41: 44003 | E41: =VLOOKUP(D41,comp!$D$5:$K$7114,2,FALSE) -> PERFURATRIZ PARA EXECUCAO DE ESTACAS SECANTES, TIPO HELICE CONTINUA COM CABECOTE DUPLO E TUBO METALICO 300 KW | J41: =VLOOKUP(D41,comp!$D$5:$K$7114,3,FALSE) -> CHP | K41: =_xlfn.XLOOKUP(D41, sin!D:D, sin!J:J, "Não Encontrado", 0,1) -> 0 | L41: =VLOOKUP(D41,comp!$D$5:$K$7114,6,FALSE) -> 149.12 | M41: =VLOOKUP(D41,comp!$D$5:$K$7114,7,FALSE) -> 0 | N41: =K41*(L41+M41) -> 0
C42: 3.9 | D42: 38538 | E42: =VLOOKUP(D42,comp!$D$5:$K$7114,2,FALSE) -> ESTACA PRE-MOLDADA MACICA DE CONCRETO VIBRADO ARMADO, PARA CARGA DE 25 T, SECAO QUADRADA DE *16 X 16*, COM ANEL METALICO INCORPORADO A PECA (SOMENTE FORNECIMENTO) | J42: =VLOOKUP(D42,comp!$D$5:$K$7114,3,FALSE) -> CHP | K42: =_xlfn.XLOOKUP(D42, sin!D:D, sin!J:J, "Não Encontrado", 0,1) -> 0 | L42: =VLOOKUP(D42,comp!$D$5:$K$7114,6,FALSE) -> 132.2291 | M42: =VLOOKUP(D42,comp!$D$5:$K$7114,7,FALSE) -> 16.890904 | N42: =K42*(L42+M42) -> 0
C43: 3.10 | D43: 38540 | E43: =VLOOKUP(D43,comp!$D$5:$K$7114,2,FALSE) -> ESTACA PRE-MOLDADA VAZADA DE CONCRETO CENTRIFUGADO, PARA CARGA DE 100 T, SECAO CIRCULAR, COM ANEL METALICO INCORPORADO A PECA (SOMENTE FORNECIMENTO) | J43: =VLOOKUP(D43,comp!$D$5:$K$7114,3,FALSE) -> CHP | K43: =_xlfn.XLOOKUP(D43, sin!D:D, sin!J:J, "Não Encontrado", 0,1) -> 0 | L43: =VLOOKUP(D43,comp!$D$5:$K$7114,6,FALSE) -> 140.88092 | M43: =VLOOKUP(D43,comp!$D$5:$K$7114,7,FALSE) -> 8.2390797 | N43: =K43*(L43+M43) -> 0
...

Sheet rel
C3: Etapa | D3: M.O. | E3: Materiais | F3: L.S. | G3: BDI | H3: Total | I3: % do Total
C4: SERVIÇOS INICIAIS | D4: =cpe!K19 -> 108712.94 | E4: =cpe!K20 -> 2955.4895 | F4: =cpe!N20 -> 23916.847 | G4: =cpe!N21 -> 33893.04 | H4: =cpe!N22 -> 169478.32 | I4: =H4/$H$20 -> 0.89559491
C5: MOVIMENTAÇÃO DE TERRA | D5: =cpe!K29 -> 0 | E5: =cpe!K30 -> 0 | F5: =cpe!N30 -> 0 | G5: =cpe!N31 -> 0 | H5: =cpe!N32 -> 0 | I5: =H5/$H$20 -> 0
C6: FUNDAÇÃO | D6: =cpe!K44 -> 0 | E6: =cpe!K45 -> 9421.29 | F6: =cpe!N45 -> 0 | G6: =cpe!N46 -> 2355.0946 | H6: =cpe!N47 -> 11776.385 | I6: =H6/$H$20 -> 0.062231384
C7: ESTRUTURA EM CONCRETO ARMADO | D7: =cpe!K64 -> 291.00858 | E7: =cpe!K65 -> 901.95142 | F7: =cpe!N65 -> 64.021889 | G7: =cpe!N66 -> 314.21507 | H7: =cpe!N67 -> 1571.197 | I7: =H7/$H$20 -> 0.0083028674
C8: PAREDE | D8: =cpe!K80 -> 0 | E8: =cpe!K81 -> 14 | F8: =cpe!N81 -> 0 | G8: =cpe!N82 -> 3.4996614 | H8: =cpe!N83 -> 17.499661 | I8: =H8/$H$20 -> 9.2475592e-05
C9: ESQUADRIAS | D9: =cpe!K87 -> 0 | E9: =cpe!K88 -> 0 | F9: =cpe!N88 -> 0 | G9: =cpe!N89 -> 0 | H9: =cpe!N90 -> 0 | I9: =H9/$H$20 -> 0
C10: COBERTURA | D10: =cpe!K99 -> 226.77196 | E10: =cpe!K100 -> 518.82804 | F10: =cpe!N100 -> 49.889832 | G10: =cpe!N101 -> 198.85322 | H10: =cpe!N102 -> 994.34305 | I10: =H10/$H$20 -> 0.0052545281
C11: IMPERMEABILIZAÇÃO | D11: =cpe!K110 -> 274.7591 | E11: =cpe!K111 -> 321.7209 | F11: =cpe!N111 -> 60.447003 | G11: =cpe!N112 -> 164.21586 | H11: =cpe!N113 -> 821.14286 | I11: =H11/$H$20 -> 0.0043392652
C12: REVESTIMENTOS | D12: =cpe!K125 -> 0 | E12: =cpe!K126 -> 143.88 | F12: =cpe!N126 -> 0 | G12: =cpe!N127 -> 35.96652 | H12: =cpe!N128 -> 179.84652 | I12: =H12/$H$20 -> 0.00095038487
C13: PREVENTIVO CONTRA INCÊNDIO | D13: =cpe!K142 -> 157.88288 | E13: =cpe!K143 -> 140.35712 | F13: =cpe!N143 -> 34.734233 | G13: =cpe!N144 -> 83.235504 | H13: =cpe!N145 -> 416.20974 | I13: =H13/$H$20 -> 0.0021994278
C14: PROJETO ELÉTRICO | D14: =cpe!K253 -> 194.71858 | E14: =cpe!K254 -> 804.17142 | F14: =cpe!N254 -> 42.838087 | G14: =cpe!N255 -> 260.40682 | H14: =cpe!N256 -> 1302.1349 | I14: =H14/$H$20 -> 0.0068810301
C15: PROJETO HIDROSSANITÁRIO | D15: =cpe!K536 -> 77.264248 | E15: =cpe!K537 -> 1413.9358 | F15: =cpe!N537 -> 16.998135 | G15: =cpe!N538 -> 377.01305 | H15: =cpe!N539 -> 1885.2112 | I15: =H15/$H$20 -> 0.0099622511
C16: LOUÇAS E METAIS | D16: =cpe!K620 -> 0 | E16: =cpe!K621 -> 0 | F16: =cpe!N621 -> 0 | G16: =cpe!N622 -> 0 | H16: =cpe!N623 -> 0 | I16: =H16/$H$20 -> 0
C17: SERVIÇOS COMPLEMENTARES | D17: =cpe!K640 -> 0 | E17: =cpe!K641 -> 0 | F17: =cpe!N641 -> 0 | G17: =cpe!N642 -> 0 | H17: =cpe!N643 -> 0 | I17: =H17/$H$20 -> 0
C18: PINTURAS | D18: =cpe!K648 -> 0 | E18: =cpe!K649 -> 175.12 | F18: =cpe!N649 -> 0 | G18: =cpe!N650 -> 43.775764 | H18: =cpe!N651 -> 218.89576 | I18: =H18/$H$20 -> 0.0011567375
C19: RETIRADA DE ENTULHO | D19: =cpe!K659 -> 54.877077 | E19: =cpe!K660 -> 392.48292 | F19: =cpe!N660 -> 12.072957 | G19: =cpe!N661 -> 114.84713 | H19: =cpe!N662 -> 574.28008 | I19: =H19/$H$20 -> 0.0030347382
C20: Totais | D20: =SUM(D4:D19) -> 109990.22 | E20: =SUM(E4:E19) -> 17203.227 | F20: =SUM(F4:F19) -> 24197.849 | G20: =SUM(G4:G19) -> 37844.163 | H20: =SUM(H4:H19) -> 189235.46 | I20: =H20/$H$20 -> 1

Sheet das
D3: TOTAL
D5: =rel!H20 -> 189235.46
O6: Mão de obra | P6: =Q6/$Q$8 -> 0.86474754 | Q6: =D13 -> 109990.22
D7: TOTAL SEM BDI | O7: Materiais | P7: =Q7/$Q$8 -> 0.13525246 | Q7: =D25 -> 17203.227
Q8: =SUM(Q6:Q7) -> 127193.45
D9: =rel!H20-rel!G20 -> 151391.3
D11: TOTAL DE MÃO DE OBRA
D13: =rel!D20 -> 109990.22
D15: TOTAL BDI
D17: =rel!G20 -> 37844.163
D19: TOTAL LS
D21: =rel!F20 -> 24197.849
D23: TOTAL MATERIAIS
D25: =rel!E20 -> 17203.227

Sheet comp
C3: CÓD. SINAPI | D3: CÓD. ITEM | E3: DESCRICAO | F3: UNID. | G3: QTD | H3: PRECO UNIT. (R$) | I3: CUSTO MATERIAL | J3: CUSTO MÃO DE OBRA | K3: CUSTO TOTAL | L3: TIPO ITEM
C5: 97141 | D5: 5678 | E5: RETROESCAVADEIRA SOBRE RODAS COM CARREGADEIRA, TRAÇÃO 4X4, POTÊNCIA LÍQ. 88 HP, CAÇAMBA CARREG. CAP. MÍN. 1 M3, CAÇAMBA RETRO CAP. 0,26 M3, PESO OPERACIONAL MÍN. 6.674 KG, PROFUNDIDADE ESCAVAÇÃO MÁX. 4,37 M - CHP DIURNO. AF_06/2014 | F5: CHP | G5: 0.0063 | H5: 149.12 | I5: 78.356334 | J5: 70.763666 | K5: =H5*G5 -> 0.939456 | L5: Mão de Obra
C6: 97141 | D6: 5679 | E6: RETROESCAVADEIRA SOBRE RODAS COM CARREGADEIRA, TRAÇÃO 4X4, POTÊNCIA LÍQ. 88 HP, CAÇAMBA CARREG. CAP. MÍN. 1 M3, CAÇAMBA RETRO CAP. 0,26 M3, PESO OPERACIONAL MÍN. 6.674 KG, PROFUNDIDADE ESCAVAÇÃO MÁX. 4,37 M - CHI DIURNO. AF_06/2014 | F6: CHP | G6: 0.0063 | H6: 149.12 | I6: 78.356334 | J6: 70.763666 | K6: =H6*G6 -> 0.939456 | L6: Mão de Obra
C7: 97141 | D7: 20078 | E7: PASTA LUBRIFICANTE PARA TUBOS E CONEXOES COM JUNTA ELASTICA, EMBALAGEM DE *400* GR (USO EM PVC, ACO, POLIETILENO E OUTROS) | F7: CHP | G7: 0.0063 | H7: 149.12 | I7: 78.356334 | J7: 70.763666 | K7: =H7*G7 -> 0.939456 | L7: INSUMO
C8: 97141 | D8: 88246 | E8: ASSENTADOR DE TUBOS COM ENCARGOS COMPLEMENTARES | F8: CHP | G8: 0.0063 | H8: 149.12 | I8: 78.356334 | J8: 70.763666 | K8: =H8*G8 -> 0.939456 | L8: Mão de Obra
C9: 97141 | D9: 88316 | E9: SERVENTE COM ENCARGOS COMPLEMENTARES | F9: CHP | G9: 0.0063 | H9: 149.12 | I9: 78.356334 | J9: 70.763666 | K9: =H9*G9 -> 0.939456 | L9: Mão de Obra
C10: 97150 | D10: 5631 | E10: ESCAVADEIRA HIDRÁULICA SOBRE ESTEIRAS, CAÇAMBA 0,80 M3, PESO OPERACIONAL 17 T, POTENCIA BRUTA 111 HP - CHP DIURNO. AF_06/2014 | F10: CHP | G10: 0.0173 | H10: 214.82 | I10: 114.09599 | J10: 100.72401 | K10: =H10*G10 -> 3.716386 | L10: Mão de Obra
C11: 97150 | D11: 5632 | E11: ESCAVADEIRA HIDRÁULICA SOBRE ESTEIRAS, CAÇAMBA 0,80 M3, PESO OPERACIONAL 17 T, POTENCIA BRUTA 111 HP - CHI DIURNO. AF_06/2014 | F11: CHI | G11: 0.0828 | H11: 92.59 | I11: 49.176742 | J11: 43.413258 | K11: =H11*G11 -> 7.666452 | L11: Mão de Obra
C12: 105369 | D12: 40421 | E12: TE RANHURADO EM FERRO FUNDIDO, DN 80 (3") | F12: CHP | G12: 0.0063 | H12: 149.12 | I12: 130.00967 | J12: 19.110332 | K12: =H12*G12 -> 0.939456 | L12: INSUMO
C13: 105377 | D13: 40418 | E13: CURVA 45 GRAUS RANHURADA EM FERRO FUNDIDO, DN 80 MM (3") | F13: CHP | G13: 0.0063 | H13: 149.12 | I13: 126.62425 | J13: 22.495746 | K13: =H13*G13 -> 0.939456 | L13: INSUMO
C14: 97173 | D14: 10997 | E14: ELETRODO REVESTIDO AWS - E7018, DIAMETRO IGUAL A 4,00 MM | F14: CHP | G14: 0.0063 | H14: 149.12 | I14: 81.601604 | J14: 67.518396 | K14: =H14*G14 -> 0.939456 | L14: INSUMO
C15: 97173 | D15: 88317 | E15: SOLDADOR COM ENCARGOS COMPLEMENTARES | F15: CHP | G15: 0.0063 | H15: 149.12 | I15: 81.601604 | J15: 67.518396 | K15: =H15*G15 -> 0.939456 | L15: Mão de Obra
C16: 97182 | D16: 88907 | E16: ESCAVADEIRA HIDRÁULICA SOBRE ESTEIRAS, CAÇAMBA 1,20 M3, PESO OPERACIONAL 21 T, POTÊNCIA BRUTA 155 HP - CHP DIURNO. AF_06/2014 | F16: CHP | G16: 0.0063 | H16: 149.12 | I16: 78.370176 | J16: 70.749824 | K16: =H16*G16 -> 0.939456 | L16: Mão de Obra
... C6300: 36274 | D6300: 36360 | E6300: JOELHO PPR, 90 GRAUS, SOLDAVEL, F/F, DN 25 MM, PARA AGUA QUENTE PREDIAL | F6300: UN | G6300: 0.261998 | H6300: 2.23 | I6300: 2.23 | J6300: 0 | K6300: =H6300*G6300 -> 0.58425554 | L6300: Insumo
C6301: 36274 | D6301: 36362 | E6301: TE NORMAL, PPR, F/F/F, SOLDAVEL, 90 GRAUS, DN 20 X 20 X 20 MM, PARA AGUA QUENTE PREDIAL | F6301: UN | G6301: 0.3726738 | H6301: 3.17 | I6301: 3.17 | J6301: 0 | K6301: =H6301*G6301 -> 1.1813759 | L6301: =IF(I6301>0,"Insumo","Mão de Obra") -> Insumo
C6302: 36274 | D6302: 38433 | E6302: JOELHO PPR, 45 GRAUS, SOLDAVEL, F/F, DN 32 MM, PARA AGUA QUENTE PREDIAL | F6302: UN | G6302: 0.7404505 | H6302: 6.3 | I6302: 6.3 | J6302: 0 | K6302: =H6302*G6302 -> 4.6648381 | L6302: =IF(I6302>0,"Insumo","Mão de Obra") -> Insumo
C6303: 36274 | D6303: 38434 | E6303: JOELHO PPR, 90 GRAUS, SOLDAVEL, F/F, DN 32 MM, PARA AGUA QUENTE PREDIAL | F6303: UN | G6303: 0.3991185 | H6303: 3.4 | I6303: 3.4 | J6303: 0 | K6303: =H6303*G6303 -> 1.3570029 | L6303: =IF(I6303>0,"Insumo","Mão de Obra") -> Insumo
C6304: 36274 | D6304: 38435 | E6304: JOELHO PPR, 90 GRAUS, SOLDAVEL, F/F, DN 40 MM, PARA AGUA QUENTE PREDIAL | F6304: UN | G6304: 0.8976494 | H6304: 7.64 | I6304: 7.64 | J6304: 0 | K6304: =H6304*G6304 -> 6.8580414 | L6304: =IF(I6304>0,"Insumo","Mão de Obra") -> Insumo
C6305: 36274 | D6305: 38436 | E6305: JOELHO PPR, 90 GRAUS, SOLDAVEL, F/F, DN 50 MM, PARA AGUA QUENTE PREDIAL | F6305: UN | G6305: 1.4877571 | H6305: 12.67 | I6305: 12.67 | J6305: 0 | K6305: =H6305*G6305 -> 18.849882 | L6305: =IF(I6305>0,"Insumo","Mão de Obra") -> Insumo
C6306: 36274 | D6306: 38437 | E6306: JOELHO PPR, 90 GRAUS, SOLDAVEL, F/F, DN 63 MM, PARA AGUA QUENTE PREDIAL | F6306: UN | G6306: 2.4133203 | H6306: 20.56 | I6306: 20.56 | J6306: 0 | K6306: =H6306*G6306 -> 49.617865 | L6306: =IF(I6306>0,"Insumo","Mão de Obra") -> Insumo
C6307: 36274 | D6307: 38438 | E6307: JOELHO PPR, 90 GRAUS, SOLDAVEL, F/F, DN 75 MM, PARA AGUA QUENTE PREDIAL | F6307: UN | G6307: 6.9990206 | H6307: 59.63 | I6307: 59.63 | J6307: 0 | K6307: =H6307*G6307 -> 417.3516 | L6307: =IF(I6307>0,"Insumo","Mão de Obra") -> Insumo
C6308: 36274 | D6308: 38439 | E6308: JOELHO PPR, 90 GRAUS, SOLDAVEL, F/F, DN 90 MM, PARA AGUA QUENTE PREDIAL | F6308: UN | G6308: 8.8937316 | H6308: 75.77 | I6308: 75.77 | J6308: 0 | K6308: =H6308*G6308 -> 673.87804 | L6308: =IF(I6308>0,"Insumo","Mão de Obra") -> Insumo
C6309: 36274 | D6309: 38440 | E6309: JOELHO PPR, 90 GRAUS, SOLDAVEL, F/F, DN 110 MM, PARA AGUA QUENTE PREDIAL | F6309: UN | G6309: 31.197845 | H6309: 265.8 | I6309: 265.8 | J6309: 0 | K6309: =H6309*G6309 -> 8292.3873 | L6309: =IF(I6309>0,"Insumo","Mão de Obra") -> Insumo
C6310: 36274 | D6310: 38441 | E6310: LUVA SIMPLES PPR, F/F, SOLDAVEL, DN 32 MM, PARA AGUA QUENTE PREDIAL | F6310: UN | G6310: 0.4015671 | H6310: 3.42 | I6310: 3.42 | J6310: 0 | K6310: =H6310*G6310 -> 1.3733595 | L6310: =IF(I6310>0,"Insumo","Mão de Obra") -> Insumo
C6311: 36274 | D6311: 38442 | E6311: LUVA SIMPLES PPR, F/F, SOLDAVEL, DN 40 MM, PARA AGUA QUENTE PREDIAL | F6311: UN | G6311: 1.1420176 | H6311: 9.72 | I6311: 9.72 | J6311: 0 | K6311: =H6311*G6311 -> 11.100411 | L6311: =IF(I6311>0,"Insumo","Mão de Obra") -> Insumo
C6312: 36274 | D6312: 38443 | E6312: LUVA SIMPLES PPR, F/F, SOLDAVEL, DN 50 MM, PARA AGUA QUENTE PREDIAL | F6312: UN | G6312: 1.3849167 | H6312: 11.79 | I6312: 11.79 | J6312: 0 | K6312: =H6312*G6312 -> 16.328168 | L6312: =IF(I6312>0,"Insumo","Mão de Obra") -> Insumo
... C7114: 45190 | D7114: 45191 | E7114: PISO EM PORCELANATO,RETIFICADO, LISO, MONOCOLOR, ACETINADO OU POLIDO, FORMATO MAIOR QUE 6400 CM2 | F7114: M2 | G7114: 1.6965465 | H7114: 101.62 | I7114: 101.62 | J7114: 0 | K7114: =H7114*G7114 -> 172.40306 | L7114: =IF(I7114>0,"Insumo","Mão de Obra") -> Insumo

Sheet sob
E3: Sobre o Sienge Plataforma
C7: O Sienge Plataforma é a principal solução de gestão da Indústria da Construção, que proporciona eficiência operacional, previsibilidade e produtividade a médias e grandes construtoras e incorporadoras. Líder no setor, atende mais de 5 mil clientes em todo o Brasil. Além de atuar como ERP especialista na construção, é a espinha dorsal tecnológica que possibilita uma gestão integrada e centralizada da operação, com conexão de mais de 40 soluções parceiras que potencializam os resultados construídos a partir do Sienge Plataforma. É uma das soluções do Sienge, o Ecossistema da Indústria da Construção e do Mercado Imobiliário, que integra a cadeia da incorporação de ponta a ponta. Clique abaixo e peça uma demonstração, ou ligue para: (48) 3027 8140
C21: PEÇA UMA DEMONSTRAÇÃO AGORA
C22: Aproveite e conheça mais materiais que podem apoiá-lo no seu dia a dia!
C23: [Conheça os materiais gratuitos do Sienge!]

Sheet Tabela Sinapi 2025 (Não mexa)
B1: 1 | C1: 2 | D1: 3 | E1: 4 | F1: 5 | G1: 6 | H1: 7 | I1: 8 | J1: 9 | K1: 10
A2: CÓD. SINAPI | B2: CÓD. ITEM | C2: DESCRICAO | D2: UNID. | E2: QTD | F2: PRECO UNIT. (R$) | G2: CUSTO MATERIAL | H2: CUSTO MÃO DE OBRA | I2: CUSTO TOTAL | J2: TIPO ITEM | K2: TIPO ITEM
A4: 97141 | B4: 5678 | C4: RETROESCAVADEIRA SOBRE RODAS COM CARREGADEIRA, TRAÇÃO 4X4, POTÊNCIA LÍQ. 88 HP, CAÇAMBA CARREG. CAP. MÍN. 1 M3, CAÇAMBA RETRO CAP. 0,26 M3, PESO OPERACIONAL MÍN. 6.674 KG, PROFUNDIDADE ESCAVAÇÃO MÁX. 4,37 M - CHP DIURNO. AF_06/2014 | D4: CHP | E4: 0.0063 | F4: 149.12 | G4: =IF(J4="INSUMO",F4*E4,0) -> 0 | H4: =IF(J4="MÃO DE OBRA",F4*E4,0) -> 0.939456 | I4: =E4*F4 -> 0.939456 | J4: Mão de Obra | K4: =IFERROR(IF(VLOOKUP(B4,comp!$D:$L,1,FALSE)=B4,"",""),"Novo")
A5: 97141 | B5: 5679 | C5: RETROESCAVADEIRA SOBRE RODAS COM CARREGADEIRA, TRAÇÃO 4X4, POTÊNCIA LÍQ. 88 HP, CAÇAMBA CARREG. CAP. MÍN. 1 M3, CAÇAMBA RETRO CAP. 0,26 M3, PESO OPERACIONAL MÍN. 6.674 KG, PROFUNDIDADE ESCAVAÇÃO MÁX. 4,37 M - CHI DIURNO. AF_06/2014 | D5: CHI | E5: 0.0304 | F5: 66.28 | G5: =IF(J5="INSUMO",F5*E5,0) -> 0 | H5: =IF(J5="MÃO DE OBRA",F5*E5,0) -> 2.014912 | I5: =E5*F5 -> 2.014912 | J5: Mão de Obra | K5: =IFERROR(IF(VLOOKUP(B5,comp!$D:$L,1,FALSE)=B5,"",""),"Novo")
A6: 97141 | B6: 20078 | C6: PASTA LUBRIFICANTE PARA TUBOS E CONEXOES COM JUNTA ELASTICA, EMBALAGEM DE *400* GR (USO EM PVC, ACO, POLIETILENO E OUTROS) | D6: UN | E6: 0.0046 | F6: 23.37 | G6: =IF(J6="INSUMO",F6*E6,0) -> 0.107502 | H6: =IF(J6="MÃO DE OBRA",F6*E6,0) -> 0 | I6: =E6*F6 -> 0.107502 | J6: INSUMO | K6: =IFERROR(IF(VLOOKUP(B6,comp!$D:$L,1,FALSE)=B6,"",""),"Novo")
A7: 97141 | B7: 88246 | C7: ASSENTADOR DE TUBOS COM ENCARGOS COMPLEMENTARES | D7: H | E7: 0.048 | F7: 23.93 | G7: =IF(J7="INSUMO",F7*E7,0) -> 0 | H7: =IF(J7="MÃO DE OBRA",F7*E7,0) -> 1.14864 | I7: =E7*F7 -> 1.14864 | J7: Mão de Obra | K7: =IFERROR(IF(VLOOKUP(B7,comp!$D:$L,1,FALSE)=B7,"",""),"Novo")
A8: 97141 | B8: 88316 | C8: SERVENTE COM ENCARGOS COMPLEMENTARES | D8: H | E8: 0.032 | F8: 26.42 | G8: =IF(J8="INSUMO",F8*E8,0) -> 0 | H8: =IF(J8="MÃO DE OBRA",F8*E8,0) -> 0.84544 | I8: =E8*F8 -> 0.84544 | J8: Mão de Obra | K8: =IFERROR(IF(VLOOKUP(B8,comp!$D:$L,1,FALSE)=B8,"",""),"Novo")
A9: 97142 | B9: 5678 | C9: RETROESCAVADEIRA SOBRE RODAS COM CARREGADEIRA, TRAÇÃO 4X4, POTÊNCIA LÍQ. 88 HP, CAÇAMBA CARREG. CAP. MÍN. 1 M3, CAÇAMBA RETRO CAP. 0,26 M3, PESO OPERACIONAL MÍN. 6.674 KG, PROFUNDIDADE ESCAVAÇÃO MÁX. 4,37 M - CHP DIURNO. AF_06/2014 | D9: CHP | E9: 0.0069 | F9: 149.12 | G9: =IF(J9="INSUMO",F9*E9,0) -> 0 | H9: =IF(J9="MÃO DE OBRA",F9*E9,0) -> 1.028928 | I9: =E9*F9 -> 1.028928 | J9: Mão de Obra | K9: =IFERROR(IF(VLOOKUP(B9,comp!$D:$L,1,FALSE)=B9,"",""),"Novo")
A10: 97150 | B10: 5631 | C10: ESCAVADEIRA HIDRÁULICA SOBRE ESTEIRAS, CAÇAMBA 0,80 M3, PESO OPERACIONAL 17 T, POTENCIA BRUTA 111 HP - CHP DIURNO. AF_06/2014 | D10: CHP | E10: 0.0173 | F10: 214.82 | G10: =IF(J10="INSUMO",F10*E10,0) -> 0 | H10: =IF(J10="MÃO DE OBRA",F10*E10,0) -> 3.716386 | I10: =E10*F10 -> 3.716386 | J10: Mão de Obra | K10: =IFERROR(IF(VLOOKUP(B10,comp!$D:$L,1,FALSE)=B10,"",""),"Novo")
A11: 97150 | B11: 5632 | C11: ESCAVADEIRA HIDRÁULICA SOBRE ESTEIRAS, CAÇAMBA 0,80 M3, PESO OPERACIONAL 17 T, POTENCIA BRUTA 111 HP - CHI DIURNO. AF_06/2014 | D11: CHI | E11: 0.0828 | F11: 92.59 | G11: =IF(J11="INSUMO",F11*E11,0) -> 0 | H11: =IF(J11="MÃO DE OBRA",F11*E11,0) -> 7.666452 | I11: =E11*F11 -> 7.666452 | J11: Mão de Obra | K11: =IFERROR(IF(VLOOKUP(B11,comp!$D:$L,1,FALSE)=B11,"",""),"Novo")
A12: 105369 | B12: 40421 | C12: TE RANHURADO EM FERRO FUNDIDO, DN 80 (3") | D12: UN | E12: 1 | F12: 53.88 | G12: =IF(J12="INSUMO",F12*E12,0) -> 53.88 | H12: =IF(J12="MÃO DE OBRA",F12*E12,0) -> 0 | I12: =E12*F12 -> 53.88 | J12: INSUMO | K12: =IFERROR(IF(VLOOKUP(B12,comp!$D:$L,1,FALSE)=B12,"",""),"Novo")
A13: 105377 | B13: 40418 | C13: CURVA 45 GRAUS RANHURADA EM FERRO FUNDIDO, DN 80 MM (3") | D13: UN | E13: 1 | F13: 32.14 | G13: =IF(J13="INSUMO",F13*E13,0) -> 32.14 | H13: =IF(J13="MÃO DE OBRA",F13*E13,0) -> 0 | I13: =E13*F13 -> 32.14 | J13: INSUMO | K13: =IFERROR(IF(VLOOKUP(B13,comp!$D:$L,1,FALSE)=B13,"",""),"Novo")
A14: 97173 | B14: 10997 | C14: ELETRODO REVESTIDO AWS - E7018, DIAMETRO IGUAL A 4,00 MM | D14: KG | E14: 0.1875 | F14: 51.84 | G14: =IF(J14="INSUMO",F14*E14,0) -> 9.72 | H14: =IF(J14="MÃO DE OBRA",F14*E14,0) -> 0 | I14: =E14*F14 -> 9.72 | J14: INSUMO | K14: =IFERROR(IF(VLOOKUP(B14,comp!$D:$L,1,FALSE)=B14,"",""),"Novo")
A15: 97173 | B15: 88317 | C15: SOLDADOR COM ENCARGOS COMPLEMENTARES | D15: H | E15: 0.564 | F15: 34.69 | G15: =IF(J15="INSUMO",F15*E15,0) -> 0 | H15: =IF(J15="MÃO DE OBRA",F15*E15,0) -> 19.56516 | I15: =E15*F15 -> 19.56516 | J15: Mão de Obra | K15: =IFERROR(IF(VLOOKUP(B15,comp!$D:$L,1,FALSE)=B15,"",""),"Novo")
... A4028: 101460 | B4028: 101372 | C4028: CURSO DE CAPACITAÇÃO PARA VIGIA DIURNO (ENCARGOS COMPLEMENTARES) - MENSALISTA | D4028: MES | E4028: 1 | F4028: 15.15 | G4028: =IF(J4028="INSUMO",F4028*E4028,0) -> 0 | H4028: =IF(J4028="MÃO DE OBRA",F4028*E4028,0) -> 15.15 | I4028: =E4028*F4028 -> 15.15 | J4028: Mão de Obra | K4028: =IFERROR(IF(VLOOKUP(B4028,comp!$D:$L,1,FALSE)=B4028,"",""),"Novo") -> Novo
A4029: 1 | B4029: 1 | C4029: ACETILENO (RECARGA DE GAS ACETILENO PARA CILINDRO DE CONJUNTO OXICORTE GRANDE) NAO INCLUI TROCA/MANUTENCAO DO CILINDRO | D4029: KG | E4029: 1 | F4029: 95,00 | G4029: 95 | H4029: 0 | I4029: 8.9 | J4029: Insumo | K4029: =IFERROR(IF(VLOOKUP(B4029,comp!$D:$L,1,FALSE)=B4029,"",""),"Novo")
A4030: 1 | B4030: 2 | C4030: OXIGENIO, RECARGA PARA CILINDRO DE CONJUNTO OXICORTE GRANDE | D4030: M3 | E4030: 0.219178 | F4030: 20,82 | G4030: 4.563286 | H4030: 0 | I4030: 21.09749 | J4030: Insumo | K4030: =IFERROR(IF(VLOOKUP(B4030,comp!$D:$L,1,FALSE)=B4030,"",""),"Novo")
A4031: 12 | B4031: 12 | C4031: ESCOVA DE ACO, COM CABO, *4 X 15* FILEIRAS DE CERDAS | D4031: UN | E4031: 1 | F4031: 8,90 | G4031: 8.9 | H4031: 0 | I4031: 0.49767648 | J4031: Insumo | K4031: =IFERROR(IF(VLOOKUP(B4031,comp!$D:$L,1,FALSE)=B4031,"",""),"Novo")
A4032: 12 | B4032: 13 | C4032: ESTOPA | D4032: KG | E4032: 1.5399628 | F4032: 13,70 | G4032: 21.09749 | H4032: 0 | I4032: 23.138708 | J4032: Insumo | K4032: =IFERROR(IF(VLOOKUP(B4032,comp!$D:$L,1,FALSE)=B4032,"",""),"Novo")
A4033: 12 | B4033: 13261 | C4033: FLANELA *30 X 40* CM | D4033: UN | E4033: 0.2369888 | F4033: 2,10 | G4033: 0.49767648 | H4033: 0 | I4033: 11.812268 | J4033: Insumo | K4033: =IFERROR(IF(VLOOKUP(B4033,comp!$D:$L,1,FALSE)=B4033,"",""),"Novo")
A4034: 12 | B4034: 38400 | C4034: VASSOURA 40 CM COM CABO | D4034: UN | E4034: 1.6124535 | F4034: 14,35 | G4034: 23.138708 | H4034: 0 | I4034: 8.3379369 | J4034: Insumo | K4034: =IFERROR(IF(VLOOKUP(B4034,comp!$D:$L,1,FALSE)=B4034,"",""),"Novo")
A4035: 12 | B4035: 38401 | C4035: RODO PARA CHAO 40 CM, COM BORRACHA DUPLA E CABO | D4035: UN | E4035: 1.1524164 | F4035: 10,25 | G4035: 11.812268 | H4035: 0 | I4035: 4.17 | J4035: Insumo | K4035: =IFERROR(IF(VLOOKUP(B4035,comp!$D:$L,1,FALSE)=B4035,"",""),"Novo")
A4036: 12 | B4036: 38402 | C4036: PA DE LIXO PLASTICA, CABO LONGO | D4036: UN | E4036: 0.9684015 | F4036: 8,61 | G4036: 8.3379369 | H4036: 0 | I4036: 7.0233388 | J4036: Insumo | K4036: =IFERROR(IF(VLOOKUP(B4036,comp!$D:$L,1,FALSE)=B4036,"",""),"Novo")
A4037: 55 | B4037: 55 | C4037: ADAPTADOR DE COMPRESSAO EM POLIPROPILENO (PP), PARA TUBO EM PEAD, 20 MM X 1/2", PARA LIGACAO PREDIAL DE AGUA (NTS 179) | D4037: UN | E4037: 1 | F4037: 4,17 | G4037: 4.17 | H4037: 0 | I4037: 3.7289283 | J4037: Insumo | K4037: =IFERROR(IF(VLOOKUP(B4037,comp!$D:$L,1,FALSE)=B4037,"",""),"Novo")
A4038: 55 | B4038: 60 | C4038: ADAPTADOR PVC, COM REGISTRO, PARA PEAD, 20 MM X 3/4", PARA LIGACAO PREDIAL DE AGUA | D4038: UN | E4038: 1.2982142 | F4038: 5,41 | G4038: 7.0233388 | H4038: 0 | I4038: 16.019035 | J4038: Insumo | K4038: =IFERROR(IF(VLOOKUP(B4038,comp!$D:$L,1,FALSE)=B4038,"",""),"Novo")
A4039: 55 | B4039: 61 | C4039: ADAPTADOR DE COMPRESSAO EM POLIPROPILENO (PP), PARA TUBO EM PEAD, 20 MM X 3/4", PARA LIGACAO PREDIAL DE AGUA (NTS 179) | D4039: UN | E4039: 0.9464285 | F4039: 3,94 | G4039: 3.7289283 | H4039: 0 | I4039: 5.4399998 | J4039: Insumo | K4039: =IFERROR(IF(VLOOKUP(B4039,comp!$D:$L,1,FALSE)=B4039,"",""),"Novo")
A4040: 55 | B4040: 62 | C4040: ADAPTADOR DE COMPRESSAO EM POLIPROPILENO (PP), PARA TUBO EM PEAD, 32 MM X 1", PARA LIGACAO PREDIAL DE AGUA (NTS 179) | D4040: UN | E4040: 1.9607142 | F4040: 8,17 | G4040: 16.019035 | H4040: 0 | I4040: 3.4675 | J4040: Insumo | K4040: =IFERROR(IF(VLOOKUP(B4040,comp!$D:$L,1,FALSE)=B4040,"",""),"Novo")
... A8867: 45190 | B8867: 45191 | C8867: PISO EM PORCELANATO,RETIFICADO, LISO, MONOCOLOR, ACETINADO OU POLIDO, FORMATO MAIOR QUE 6400 CM2 | D8867: M2 | E8867: 1.6965465 | F8867: 101,62 | G8867: 172.40306 | H8867: 0 | I8867: 0 | J8867: Insumo | K8867: =IFERROR(IF(VLOOKUP(B8867,comp!$D:$L,1,FALSE)=B8867,"",""),"Novo")
